<?xml version="1.0" ?>

<robot name="faro_description" xmlns:xacro="http://www.ros.org/wiki/xacro" >
  
  <xacro:include filename="$(find faro_description)/urdf/sensor.xacro"/>
  <xacro:include filename="$(find faro_description)/urdf/common_properties.xacro"/>

  <!-- Dummy for no warning -->    
  <link name="dummy"></link>
  <joint name="dummy_joint" type="fixed">
      <parent link="dummy" />
      <child link="base_link" />
  </joint>

  <link
    name="base_link">
    <inertial>
      <origin
        xyz="0.00873430427479388 -0.00175292065981603 -1.60683999922646E-05"
        rpy="0 0 0" />
      <mass
        value="0.451148910388453" />
      <inertia
        ixx="0.000741612731246182"
        ixy="1.64659716773886E-06"
        ixz="1.51707793234015E-07"
        iyy="0.00220273812328352"
        iyz="-9.17558592682493E-09"
        izz="0.00147205616680342" />
    </inertial>
    <visual>
      <origin
        xyz="0 0 0"
        rpy="0 0 0" />
      <geometry>
        <mesh
          filename="package://faro_description/meshes/faro.dae" />
      </geometry>
      <material
        name="">
        <color
          rgba="0.498039215686275 0.498039215686275 0.498039215686275 1" />
      </material>
    </visual>
    <collision>
      <origin
        xyz="0 0 0"
        rpy="0 0 0" />
      <geometry>
        <mesh
          filename="package://faro_description/meshes/base_link.STL" />
      </geometry>
    </collision>
  </link>
  <link
    name="RodaEsferica_Link">
    <inertial>
      <origin
        xyz="0.068659 -0.017264 0.00018379"
        rpy="0 0 0" />
      <mass
        value="0.020844" />
      <inertia
        ixx="9.8497E-07"
        ixy="1.4029E-22"
        ixz="-7.8188E-23"
        iyy="1.4E-06"
        iyz="1.592E-22"
        izz="8.9118E-07" />
    </inertial>
    <visual>
      <origin
        xyz="0 0 0"
        rpy="0 0 0" />
      <geometry>
        <mesh
          filename="package://faro_description/meshes/RodaEsferica_Link.STL" />
      </geometry>
      <material
        name="">
        <color
          rgba="0.89804 0.89804 0.89804 1" />
      </material>
    </visual>
    <collision>
      <origin
        xyz="0 0 0"
        rpy="0 0 0" />
      <geometry>
        <mesh
          filename="package://faro_description/meshes/RodaEsferica_Link.STL" />
      </geometry>
    </collision>
  </link>
  <joint
    name="RodaEsferica_Joint"
    type="fixed">
    <origin
      xyz="0 0 0"
      rpy="1.5708 0 0" />
    <parent
      link="base_link" />
    <child
      link="RodaEsferica_Link" />
    <axis
      xyz="0 0 0" />
    <dynamics
      friction="0" />
  </joint>
  <link
    name="RodaEsquerda_Link">
    <inertial>
      <origin
        xyz="-2.8093E-09 -1.6256E-09 0.00047467"
        rpy="0 0 0" />
      <mass
        value="0.050589" />
      <inertia
        ixx="2.8263E-05"
        ixy="-1.4586E-12"
        ixz="1.5929E-12"
        iyy="2.8263E-05"
        iyz="1.4235E-12"
        izz="4.8345E-05" />
    </inertial>
    <visual>
      <origin
        xyz="0 0 0"
        rpy="0 0 0" />
      <geometry>
        <mesh
          filename="package://faro_description/meshes/RodaEsquerda_Link.STL" />
      </geometry>
      <material
        name="">
        <color
          rgba="1 1 0 1" />
      </material>
    </visual>
    <collision>
      <origin
        xyz="0 0 0"
        rpy="0 0 0" />
      <geometry>
        <mesh
          filename="package://faro_description/meshes/RodaEsquerda_Link.STL" />
      </geometry>
    </collision>
  </link>
  <joint
    name="RodaEsquerda_Joint"
    type="revolute">
    <origin
      xyz="-0.053091 0.098228 0.011373"
      rpy="1.5708 -0.58968 3.1416" />
    <parent
      link="base_link" />
    <child
      link="RodaEsquerda_Link" />
    <axis
      xyz="0 0 -1" />
    <limit
      lower="-3.14"
      upper="3.14"
      effort="0"
      velocity="0" />
  </joint>
  <link
    name="RodaDireita_Link">
    <inertial>
      <origin
        xyz="0 0 0"
        rpy="0 0 0" />
      <mass
        value="0" />
      <inertia
        ixx="0"
        ixy="0"
        ixz="0"
        iyy="0"
        iyz="0"
        izz="0" />
    </inertial>
    <visual>
      <origin
        xyz="0 0 0"
        rpy="0 0 0" />
      <geometry>
        <mesh
          filename="package://faro_description/meshes/RodaDireita_Link.STL" />
      </geometry>
      <material
        name="">
        <color
          rgba="1 1 1 1" />
      </material>
    </visual>
    <collision>
      <origin
        xyz="0 0 0"
        rpy="0 0 0" />
      <geometry>
        <mesh
          filename="package://faro_description/meshes/RodaDireita_Link.STL" />
      </geometry>
    </collision>
  </link>
  <joint
    name="RodaDireita_Joint"
    type="revolute">
    <origin
      xyz="-0.053091 -0.098296 0.011373"
      rpy="1.5708 -1.1528 0" />
    <parent
      link="base_link" />
    <child
      link="RodaDireita_Link" />
    <axis
      xyz="0 0 -1" />
    <limit
      lower="-3.14"
      upper="3.14"
      effort="0"
      velocity="0" />
  </joint>

  <gazebo reference="base_link">
    <material>Gazebo/Green</material>
  </gazebo>

  
  <gazebo>
    <plugin filename="libgazebo_ros_diff_drive.so" name="differential_drive_controller">
      <rosDebugLevel>na</rosDebugLevel>
      <legacyMode>false</legacyMode>
      <alwaysOn>true</alwaysOn>
      <updateRate>20</updateRate>
      <leftJoint>RodaEsquerda_Joint</leftJoint>
      <publishWheelTF>false</publishWheelTF>
      <rightJoint>RodaDireita_Joint</rightJoint>
      <wheelSeparation>0.3</wheelSeparation>
      <publishWheelJointState>false</publishWheelJointState>
      <wheelDiameter>0.2</wheelDiameter>
      <wheelAcceleration>0</wheelAcceleration>
      <wheelTorque>5</wheelTorque>
      <odometrySource>1</odometrySource>
      <torque>0.1</torque>
      <commandTopic>cmd_vel</commandTopic>
      <odometryTopic>odom</odometryTopic>
      <publishOdomTF>true</publishOdomTF>
      <publishTf>1</publishTf>
      <odometryFrame>odom</odometryFrame>
      <robotBaseFrame>base_link</robotBaseFrame>
    </plugin>
  </gazebo>


  <!-- Sensor LF -->
  <xacro:sensor x="0.145" y="0.03" z="0.007" parent="base_link"/>
    
</robot>