<?xml version="1.0" encoding="utf-8"?>
<!-- This URDF was automatically created by SolidWorks to URDF Exporter! Originally created by Stephen Brawner (brawner@gmail.com) 
     Commit Version: 1.6.0-4-g7f85cfe  Build Version: 1.6.7995.38578
     For more information, please see http://wiki.ros.org/sw_urdf_exporter -->
<robot
  name="faro_description">
  <link
    name="Base1_link">
    <inertial>
      <origin
        xyz="5.1713E-10 -7.3629E-10 -8.9432E-11"
        rpy="0 0 0" />
      <mass
        value="0.57317" />
      <inertia
        ixx="0.00079912"
        ixy="1.6466E-06"
        ixz="1.5171E-07"
        iyy="0.0022607"
        iyz="-9.1778E-09"
        izz="0.0015696" />
    </inertial>
    <visual>
      <origin
        xyz="0 0 0"
        rpy="0 0 0" /> 
      <geometry>
        <mesh
          filename="package://faro_description/meshes/Base1_link.STL" />
      </geometry>
      <material
        name="">
        <color
          rgba="0.79216 0.81961 0.93333 1" />
      </material>
    </visual>
    <collision>
      <origin
        xyz="0 0 0"
        rpy="0 0 0" />
      <geometry>
        <mesh
          filename="package://faro_description/meshes/Base1_link.STL" />
      </geometry>
    </collision>
  </link>
  <link
    name="RodaEsquerda_Link">
    <inertial>
      <origin
        xyz="-2.8093E-09 -1.6256E-09 0.00047467"
        rpy="0 0 0" />
      <mass
        value="0.050589" />
      <inertia
        ixx="2.8263E-05"
        ixy="-1.4586E-12"
        ixz="1.5929E-12"
        iyy="2.8263E-05"
        iyz="1.4235E-12"
        izz="4.8345E-05" />
    </inertial>
    <visual>
      <origin
        xyz="0 0 0"
        rpy="0 0 0" />
      <geometry>
        <mesh
          filename="package://faro_description/meshes/RodaEsquerda_Link.STL" />
      </geometry>
      <material
        name="">
        <color
          rgba="1 1 0 1" />
      </material>
    </visual>
    <collision>
      <origin
        xyz="0 0 0"
        rpy="0 0 0" />
      <geometry>
        <mesh
          filename="package://faro_description/meshes/RodaEsquerda_Link.STL" />
      </geometry>
    </collision>
  </link>
  <joint
    name="RodaEsquerda_Joint"
    type="revolute">
    <origin
      xyz="-0.053091 0.098228 0.011373"
      rpy="1.5708 -0.58968 3.1416" />
    <parent
      link="Base1_link" />
    <child
      link="RodaEsquerda_Link" />
    <axis
      xyz="0 0 0" />
    <limit
      lower="-3.14"
      upper="3.14"
      effort="0"
      velocity="0" />
  </joint>
  <link
    name="RodaDireita_Link">
    <inertial>
      <origin
        xyz="-1.5728E-09 1.9775E-09 0.00047467"
        rpy="0 0 0" />
      <mass
        value="0.050589" />
      <inertia
        ixx="2.8263E-05"
        ixy="1.6684E-12"
        ixz="5.6717E-13"
        iyy="2.8263E-05"
        iyz="-1.6358E-12"
        izz="4.8345E-05" />
    </inertial>
    <visual>
      <origin
        xyz="0 0 0"
        rpy="0 0 0" />
      <geometry>
        <mesh
          filename="package://faro_description/meshes/RodaDireita_Link.STL" />
      </geometry>
      <material
        name="">
        <color
          rgba="1 1 0 1" />
      </material>
    </visual>
    <collision>
      <origin
        xyz="0 0 0"
        rpy="0 0 0" />
      <geometry>
        <mesh
          filename="package://faro_description/meshes/RodaDireita_Link.STL" />
      </geometry>
    </collision>
  </link>
  <joint
    name="RodaDireita_Joint"
    type="revolute">
    <origin
      xyz="-0.053091 -0.098296 0.011373"
      rpy="1.5708 -1.1528 0" />
    <parent
      link="Base1_link" />
    <child
      link="RodaDireita_Link" />
    <axis
      xyz="0 0 0" />
    <limit
      lower="-3.14"
      upper="3.14"
      effort="0"
      velocity="0" />
  </joint>
  <link
    name="Base2_Link">
    <inertial>
      <origin
        xyz="9.0531E-18 -0.0094854 -1.3878E-17"
        rpy="0 0 0" />
      <mass
        value="0.009989" />
      <inertia
        ixx="6.8289E-07"
        ixy="1.5431E-22"
        ixz="6.5653E-23"
        iyy="1.1917E-06"
        iyz="-1.3096E-22"
        izz="7.7668E-07" />
    </inertial>
    <visual>
      <origin
        xyz="0 0 0"
        rpy="0 0 0" />
      <geometry>
        <mesh
          filename="package://faro_description/meshes/Base2_Link.STL" />
      </geometry>
      <material
        name="">
        <color
          rgba="0.89804 0.89804 0.89804 1" />
      </material>
    </visual>
    <collision>
      <origin
        xyz="0 0 0"
        rpy="0 0 0" />
      <geometry>
        <mesh
          filename="package://faro_description/meshes/Base2_Link.STL" />
      </geometry>
    </collision>
  </link>
  <joint
    name="Base2_Joint"
    type="fixed">
    <origin
      xyz="0.068659 -0.00018379 -0.0050882"
      rpy="1.5708 0 -1.5708" />
    <parent
      link="Base1_link" />
    <child
      link="Base2_Link" />
    <axis
      xyz="0 0 0" />
  </joint>
  <link
    name="Esfera_Link">
    <inertial>
      <origin
        xyz="0 0 0"
        rpy="0 0 0" />
      <mass
        value="0.010855" />
      <inertia
        ixx="2.0829E-07"
        ixy="-6.6174E-24"
        ixz="0"
        iyy="2.0829E-07"
        iyz="-6.6174E-24"
        izz="2.0829E-07" />
    </inertial>
    <visual>
      <origin
        xyz="0 0 0"
        rpy="0 0 0" />
      <geometry>
        <mesh
          filename="package://faro_description/meshes/Esfera_Link.STL" />
      </geometry>
      <material
        name="">
        <color
          rgba="0.89804 0.89804 0.89804 1" />
      </material>
    </visual>
    <collision>
      <origin
        xyz="0 0 0"
        rpy="0 0 0" />
      <geometry>
        <mesh
          filename="package://faro_description/meshes/Esfera_Link.STL" />
      </geometry>
    </collision>
  </link>
  <joint
    name="Esfera_Joint"
    type="revolute">
    <origin
      xyz="0 -0.014652 0"
      rpy="0.50086 -1.1467 -0.05132" />
    <parent
      link="Base2_Link" />
    <child
      link="Esfera_Link" />
    <axis
      xyz="0 0 0" />
    <limit
      lower="0"
      upper="0"
      effort="0"
      velocity="0" />
  </joint>
</robot>