<?xml version="1.0" encoding="utf-8"?>
<!-- This URDF was automatically created by SolidWorks to URDF Exporter! Originally created by Stephen Brawner (brawner@gmail.com) 
     Commit Version: 1.6.0-4-g7f85cfe  Build Version: 1.6.7995.38578
     For more information, please see http://wiki.ros.org/sw_urdf_exporter -->
<robot
  name="URDF 2">
  <link
    name="base_link">
    <inertial>
      <origin
        xyz="0.00838566222314017 -0.00175945347875662 -0.000186169118924884"
        rpy="0 0 0" />
      <mass
        value="0.449886789963798" />
      <inertia
        ixx="0.00074159205310207"
        ixy="1.64362520304945E-06"
        ixz="1.52064449715939E-07"
        iyy="0.00220265043035818"
        iyz="-7.38634321348047E-09"
        izz="0.00147198182450226" />
    </inertial>
    <visual>
      <origin
        xyz="0 0 0"
        rpy="0 0 0" />
      <geometry>
        <mesh
          filename="package://URDF 2/meshes/base_link.STL" />
      </geometry>
      <material
        name="">
        <color
          rgba="0.537254901960784 0.349019607843137 0.337254901960784 1" />
      </material>
    </visual>
    <collision>
      <origin
        xyz="0 0 0"
        rpy="0 0 0" />
      <geometry>
        <mesh
          filename="package://URDF 2/meshes/base_link.STL" />
      </geometry>
    </collision>
  </link>
  <link
    name="bola1_Link">
    <inertial>
      <origin
        xyz="-1.57279833080948E-09 1.97751798269863E-09 0.000474666390947093"
        rpy="0 0 0" />
      <mass
        value="0.0505890697331487" />
      <inertia
        ixx="2.82629424828748E-05"
        ixy="1.66841252846015E-12"
        ixz="5.67166577200729E-13"
        iyy="2.8262941544918E-05"
        iyz="-1.63581654999165E-12"
        izz="4.83451973964662E-05" />
    </inertial>
    <visual>
      <origin
        xyz="0 0 0"
        rpy="0 0 0" />
      <geometry>
        <mesh
          filename="package://URDF 2/meshes/bola1_Link.STL" />
      </geometry>
      <material
        name="">
        <color
          rgba="1 1 0 1" />
      </material>
    </visual>
    <collision>
      <origin
        xyz="0 0 0"
        rpy="0 0 0" />
      <geometry>
        <mesh
          filename="package://URDF 2/meshes/bola1_Link.STL" />
      </geometry>
    </collision>
  </link>
  <joint
    name="bola1_joint"
    type="revolute">
    <origin
      xyz="-0.053091 -0.098296 0.011373"
      rpy="1.5708 -1.1528 0" />
    <parent
      link="base_link" />
    <child
      link="bola1_Link" />
    <axis
      xyz="0 0 0" />
    <limit
      lower="-3.14"
      upper="3.14"
      effort="0"
      velocity="0" />
  </joint>
  <link
    name="bola2_Link">
    <inertial>
      <origin
        xyz="-2.8092860329676E-09 -1.62563564692908E-09 0.000474666987463443"
        rpy="0 0 0" />
      <mass
        value="0.0505890699400185" />
      <inertia
        ixx="2.82629417091322E-05"
        ixy="-1.45857255869189E-12"
        ixz="1.59293683683434E-12"
        iyy="2.82629426261707E-05"
        iyz="1.42351069917057E-12"
        izz="4.8345197400437E-05" />
    </inertial>
    <visual>
      <origin
        xyz="0 0 0"
        rpy="0 0 0" />
      <geometry>
        <mesh
          filename="package://URDF 2/meshes/bola2_Link.STL" />
      </geometry>
      <material
        name="">
        <color
          rgba="1 1 0 1" />
      </material>
    </visual>
    <collision>
      <origin
        xyz="0 0 0"
        rpy="0 0 0" />
      <geometry>
        <mesh
          filename="package://URDF 2/meshes/bola2_Link.STL" />
      </geometry>
    </collision>
  </link>
  <joint
    name="bola2_joint"
    type="revolute">
    <origin
      xyz="-0.053091 0.098228 0.011373"
      rpy="1.5708 -0.58968 3.1416" />
    <parent
      link="base_link" />
    <child
      link="bola2_Link" />
    <axis
      xyz="0 0 0" />
    <limit
      lower="-3.14"
      upper="3.14"
      effort="0"
      velocity="0" />
  </joint>
  <link
    name="suporte1_Link">
    <inertial>
      <origin
        xyz="-6.93889390390723E-18 0.00638467713248998 0"
        rpy="0 0 0" />
      <mass
        value="0.00418212896344437" />
      <inertia
        ixx="2.09742622220717E-07"
        ixy="-2.33935383916263E-23"
        ixz="-3.97046694025453E-23"
        iyy="3.85687250302628E-07"
        iyz="5.4813509514362E-23"
        izz="2.09742622220717E-07" />
    </inertial>
    <visual>
      <origin
        xyz="0 0 0"
        rpy="0 0 0" />
      <geometry>
        <mesh
          filename="package://URDF 2/meshes/suporte1_Link.STL" />
      </geometry>
      <material
        name="">
        <color
          rgba="0.898039215686275 0.898039215686275 0.898039215686275 1" />
      </material>
    </visual>
    <collision>
      <origin
        xyz="0 0 0"
        rpy="0 0 0" />
      <geometry>
        <mesh
          filename="package://URDF 2/meshes/suporte1_Link.STL" />
      </geometry>
    </collision>
  </link>
  <joint
    name="suporte1_joint"
    type="fixed">
    <origin
      xyz="0.068659 -0.00018379 -0.0068594"
      rpy="-1.5708 0 0.99209" />
    <parent
      link="base_link" />
    <child
      link="suporte1_Link" />
    <axis
      xyz="0 0 0" />
  </joint>
  <link
    name="bola_Link">
    <inertial>
      <origin
        xyz="6.08106567458119E-05 -0.00258830988134135 0.00126334434939675"
        rpy="0 0 0" />
      <mass
        value="0.0108551890743605" />
      <inertia
        ixx="2.08289240912705E-07"
        ixy="-6.61744490042422E-24"
        ixz="0"
        iyy="2.08289240912705E-07"
        iyz="-6.61744490042422E-24"
        izz="2.08289240912705E-07" />
    </inertial>
    <visual>
      <origin
        xyz="0 0 0"
        rpy="0 0 0" />
      <geometry>
        <mesh
          filename="package://URDF 2/meshes/bola_Link.STL" />
      </geometry>
      <material
        name="">
        <color
          rgba="0.898039215686275 0.898039215686275 0.898039215686275 1" />
      </material>
    </visual>
    <collision>
      <origin
        xyz="0 0 0"
        rpy="0 0 0" />
      <geometry>
        <mesh
          filename="package://URDF 2/meshes/bola_Link.STL" />
      </geometry>
    </collision>
  </link>
  <joint
    name="bola_joint"
    type="continuous">
    <origin
      xyz="0 0.01 0"
      rpy="0.46756 -0.56834 3.1165" />
    <parent
      link="suporte1_Link" />
    <child
      link="bola_Link" />
    <axis
      xyz="0 0 0" />
  </joint>
  <link
    name="suporte2_Link">
    <inertial>
      <origin
        xyz="1.46909394371786E-17 -0.00867173136296422 2.77555756156289E-17"
        rpy="0 0 0" />
      <mass
        value="0.00580682672070605" />
      <inertia
        ixx="4.73150858037673E-07"
        ixy="1.28523937720156E-22"
        ixz="4.91835551020675E-23"
        iyy="8.06008671734035E-07"
        iyz="-7.61350549863291E-23"
        izz="5.6693570010674E-07" />
    </inertial>
    <visual>
      <origin
        xyz="0 0 0"
        rpy="0 0 0" />
      <geometry>
        <mesh
          filename="package://URDF 2/meshes/suporte2_Link.STL" />
      </geometry>
      <material
        name="">
        <color
          rgba="0.898039215686275 0.898039215686275 0.898039215686275 1" />
      </material>
    </visual>
    <collision>
      <origin
        xyz="0 0 0"
        rpy="0 0 0" />
      <geometry>
        <mesh
          filename="package://URDF 2/meshes/suporte2_Link.STL" />
      </geometry>
    </collision>
  </link>
  <joint
    name="suporte2_joint"
    type="fixed">
    <origin
      xyz="0.068659 -0.00018379 -0.0068594"
      rpy="1.5708 0 -1.5708" />
    <parent
      link="base_link" />
    <child
      link="suporte2_Link" />
    <axis
      xyz="0 0 0" />
  </joint>
</robot>